2019-04-28 10:42:56,649 - /usr/local/lib/python2.7/site-packages/apscheduler/schedulers/base.py[line:162] - INFO: Scheduler started
2019-04-28 10:42:56,655 - /usr/local/lib/python2.7/site-packages/apscheduler/schedulers/base.py[line:937] - DEBUG: Looking for jobs to run
2019-04-28 10:42:56,656 - /usr/local/lib/python2.7/site-packages/apscheduler/schedulers/base.py[line:1013] - DEBUG: No jobs; waiting until a job is added
2019-04-28 10:43:14,637 - /usr/local/lib/python2.7/site-packages/django/core/handlers/exception.py[line:135] - ERROR: Internal Server Error: /caseApiAddOldPost/9
Traceback (most recent call last):
  File "/usr/local/lib/python2.7/site-packages/django/core/handlers/exception.py", line 41, in inner
    response = get_response(request)
  File "/usr/local/lib/python2.7/site-packages/django/core/handlers/base.py", line 187, in _get_response
    response = self.process_exception_by_middleware(e, request)
  File "/usr/local/lib/python2.7/site-packages/django/core/handlers/base.py", line 185, in _get_response
    response = wrapped_callback(request, *callback_args, **callback_kwargs)
  File "/Users/sherry/Desktop/pythonProject/Django/django_web/api/caseApiView.py", line 228, in caseApiAddOldPost
    fi = uploadFile.objects.get(id=h.file_id)
  File "/usr/local/lib/python2.7/site-packages/django/db/models/manager.py", line 85, in manager_method
    return getattr(self.get_queryset(), name)(*args, **kwargs)
  File "/usr/local/lib/python2.7/site-packages/django/db/models/query.py", line 380, in get
    self.model._meta.object_name
DoesNotExist: uploadFile matching query does not exist.
2019-04-28 10:43:19,134 - /usr/local/lib/python2.7/site-packages/django/core/handlers/exception.py[line:135] - ERROR: Internal Server Error: /caseApiAddOldPost/9
Traceback (most recent call last):
  File "/usr/local/lib/python2.7/site-packages/django/core/handlers/exception.py", line 41, in inner
    response = get_response(request)
  File "/usr/local/lib/python2.7/site-packages/django/core/handlers/base.py", line 187, in _get_response
    response = self.process_exception_by_middleware(e, request)
  File "/usr/local/lib/python2.7/site-packages/django/core/handlers/base.py", line 185, in _get_response
    response = wrapped_callback(request, *callback_args, **callback_kwargs)
  File "/Users/sherry/Desktop/pythonProject/Django/django_web/api/caseApiView.py", line 228, in caseApiAddOldPost
    fi = uploadFile.objects.get(id=h.file_id)
  File "/usr/local/lib/python2.7/site-packages/django/db/models/manager.py", line 85, in manager_method
    return getattr(self.get_queryset(), name)(*args, **kwargs)
  File "/usr/local/lib/python2.7/site-packages/django/db/models/query.py", line 380, in get
    self.model._meta.object_name
DoesNotExist: uploadFile matching query does not exist.
2019-04-28 10:44:00,602 - /usr/local/lib/python2.7/site-packages/django/core/handlers/exception.py[line:135] - ERROR: Internal Server Error: /apiEdit/29
Traceback (most recent call last):
  File "/usr/local/lib/python2.7/site-packages/django/core/handlers/exception.py", line 41, in inner
    response = get_response(request)
  File "/usr/local/lib/python2.7/site-packages/django/core/handlers/base.py", line 187, in _get_response
    response = self.process_exception_by_middleware(e, request)
  File "/usr/local/lib/python2.7/site-packages/django/core/handlers/base.py", line 185, in _get_response
    response = wrapped_callback(request, *callback_args, **callback_kwargs)
  File "/usr/local/lib/python2.7/site-packages/django/contrib/auth/decorators.py", line 23, in _wrapped_view
    return view_func(request, *args, **kwargs)
  File "/Users/sherry/Desktop/pythonProject/Django/django_web/api/apiView.py", line 194, in apiEdit
    f = uploadFile.objects.get(id=j.file_id)
  File "/usr/local/lib/python2.7/site-packages/django/db/models/manager.py", line 85, in manager_method
    return getattr(self.get_queryset(), name)(*args, **kwargs)
  File "/usr/local/lib/python2.7/site-packages/django/db/models/query.py", line 380, in get
    self.model._meta.object_name
DoesNotExist: uploadFile matching query does not exist.
2019-04-28 10:44:12,811 - /usr/local/lib/python2.7/site-packages/django/core/handlers/exception.py[line:135] - ERROR: Internal Server Error: /apiEdit/27
Traceback (most recent call last):
  File "/usr/local/lib/python2.7/site-packages/django/core/handlers/exception.py", line 41, in inner
    response = get_response(request)
  File "/usr/local/lib/python2.7/site-packages/django/core/handlers/base.py", line 187, in _get_response
    response = self.process_exception_by_middleware(e, request)
  File "/usr/local/lib/python2.7/site-packages/django/core/handlers/base.py", line 185, in _get_response
    response = wrapped_callback(request, *callback_args, **callback_kwargs)
  File "/usr/local/lib/python2.7/site-packages/django/contrib/auth/decorators.py", line 23, in _wrapped_view
    return view_func(request, *args, **kwargs)
  File "/Users/sherry/Desktop/pythonProject/Django/django_web/api/apiView.py", line 194, in apiEdit
    f = uploadFile.objects.get(id=j.file_id)
  File "/usr/local/lib/python2.7/site-packages/django/db/models/manager.py", line 85, in manager_method
    return getattr(self.get_queryset(), name)(*args, **kwargs)
  File "/usr/local/lib/python2.7/site-packages/django/db/models/query.py", line 380, in get
    self.model._meta.object_name
DoesNotExist: uploadFile matching query does not exist.
2019-04-28 10:45:06,598 - /usr/local/lib/python2.7/site-packages/django/core/handlers/exception.py[line:135] - ERROR: Internal Server Error: /copyApi/16
Traceback (most recent call last):
  File "/usr/local/lib/python2.7/site-packages/django/core/handlers/exception.py", line 41, in inner
    response = get_response(request)
  File "/usr/local/lib/python2.7/site-packages/django/core/handlers/base.py", line 187, in _get_response
    response = self.process_exception_by_middleware(e, request)
  File "/usr/local/lib/python2.7/site-packages/django/core/handlers/base.py", line 185, in _get_response
    response = wrapped_callback(request, *callback_args, **callback_kwargs)
  File "/usr/local/lib/python2.7/site-packages/django/contrib/auth/decorators.py", line 23, in _wrapped_view
    return view_func(request, *args, **kwargs)
  File "/Users/sherry/Desktop/pythonProject/Django/django_web/api/apiView.py", line 484, in copyApi
    f = uploadFile.objects.get(id=j.file_id)
  File "/usr/local/lib/python2.7/site-packages/django/db/models/manager.py", line 85, in manager_method
    return getattr(self.get_queryset(), name)(*args, **kwargs)
  File "/usr/local/lib/python2.7/site-packages/django/db/models/query.py", line 380, in get
    self.model._meta.object_name
DoesNotExist: uploadFile matching query does not exist.
2019-04-28 10:50:59,600 - /usr/local/lib/python2.7/site-packages/django/core/handlers/exception.py[line:135] - ERROR: Internal Server Error: /apiEdit/16
Traceback (most recent call last):
  File "/usr/local/lib/python2.7/site-packages/django/core/handlers/exception.py", line 41, in inner
    response = get_response(request)
  File "/usr/local/lib/python2.7/site-packages/django/core/handlers/base.py", line 187, in _get_response
    response = self.process_exception_by_middleware(e, request)
  File "/usr/local/lib/python2.7/site-packages/django/core/handlers/base.py", line 185, in _get_response
    response = wrapped_callback(request, *callback_args, **callback_kwargs)
  File "/usr/local/lib/python2.7/site-packages/django/contrib/auth/decorators.py", line 23, in _wrapped_view
    return view_func(request, *args, **kwargs)
  File "/Users/sherry/Desktop/pythonProject/Django/django_web/api/apiView.py", line 194, in apiEdit
    f = uploadFile.objects.get(id=j.file_id)
  File "/usr/local/lib/python2.7/site-packages/django/db/models/manager.py", line 85, in manager_method
    return getattr(self.get_queryset(), name)(*args, **kwargs)
  File "/usr/local/lib/python2.7/site-packages/django/db/models/query.py", line 380, in get
    self.model._meta.object_name
DoesNotExist: uploadFile matching query does not exist.
2019-04-28 10:53:44,294 - /usr/local/lib/python2.7/site-packages/django/core/handlers/exception.py[line:135] - ERROR: Internal Server Error: /apiEdit/16
Traceback (most recent call last):
  File "/usr/local/lib/python2.7/site-packages/django/core/handlers/exception.py", line 41, in inner
    response = get_response(request)
  File "/usr/local/lib/python2.7/site-packages/django/core/handlers/base.py", line 187, in _get_response
    response = self.process_exception_by_middleware(e, request)
  File "/usr/local/lib/python2.7/site-packages/django/core/handlers/base.py", line 185, in _get_response
    response = wrapped_callback(request, *callback_args, **callback_kwargs)
  File "/usr/local/lib/python2.7/site-packages/django/contrib/auth/decorators.py", line 23, in _wrapped_view
    return view_func(request, *args, **kwargs)
  File "/Users/sherry/Desktop/pythonProject/Django/django_web/api/apiView.py", line 194, in apiEdit
    f = uploadFile.objects.get(id=j.file_id)
  File "/usr/local/lib/python2.7/site-packages/django/db/models/manager.py", line 85, in manager_method
    return getattr(self.get_queryset(), name)(*args, **kwargs)
  File "/usr/local/lib/python2.7/site-packages/django/db/models/query.py", line 380, in get
    self.model._meta.object_name
DoesNotExist: uploadFile matching query does not exist.
2019-04-28 11:34:08,794 - /usr/local/lib/python2.7/site-packages/django/core/handlers/exception.py[line:135] - ERROR: Internal Server Error: /fileList/
Traceback (most recent call last):
  File "/usr/local/lib/python2.7/site-packages/django/core/handlers/exception.py", line 41, in inner
    response = get_response(request)
  File "/usr/local/lib/python2.7/site-packages/django/core/handlers/base.py", line 187, in _get_response
    response = self.process_exception_by_middleware(e, request)
  File "/usr/local/lib/python2.7/site-packages/django/core/handlers/base.py", line 185, in _get_response
    response = wrapped_callback(request, *callback_args, **callback_kwargs)
  File "/Users/sherry/Desktop/pythonProject/Django/django_web/api/uploadView.py", line 36, in fileList
    m = ApiCase.objects.get(id=a.api_id)
  File "/usr/local/lib/python2.7/site-packages/django/db/models/manager.py", line 85, in manager_method
    return getattr(self.get_queryset(), name)(*args, **kwargs)
  File "/usr/local/lib/python2.7/site-packages/django/db/models/query.py", line 380, in get
    self.model._meta.object_name
DoesNotExist: ApiCase matching query does not exist.
2019-04-28 11:34:11,512 - /usr/local/lib/python2.7/site-packages/django/core/handlers/exception.py[line:135] - ERROR: Internal Server Error: /fileList/
Traceback (most recent call last):
  File "/usr/local/lib/python2.7/site-packages/django/core/handlers/exception.py", line 41, in inner
    response = get_response(request)
  File "/usr/local/lib/python2.7/site-packages/django/core/handlers/base.py", line 187, in _get_response
    response = self.process_exception_by_middleware(e, request)
  File "/usr/local/lib/python2.7/site-packages/django/core/handlers/base.py", line 185, in _get_response
    response = wrapped_callback(request, *callback_args, **callback_kwargs)
  File "/Users/sherry/Desktop/pythonProject/Django/django_web/api/uploadView.py", line 36, in fileList
    m = ApiCase.objects.get(id=a.api_id)
  File "/usr/local/lib/python2.7/site-packages/django/db/models/manager.py", line 85, in manager_method
    return getattr(self.get_queryset(), name)(*args, **kwargs)
  File "/usr/local/lib/python2.7/site-packages/django/db/models/query.py", line 380, in get
    self.model._meta.object_name
DoesNotExist: ApiCase matching query does not exist.
2019-04-28 11:34:11,739 - /usr/local/lib/python2.7/site-packages/django/core/handlers/exception.py[line:135] - ERROR: Internal Server Error: /fileList/
Traceback (most recent call last):
  File "/usr/local/lib/python2.7/site-packages/django/core/handlers/exception.py", line 41, in inner
    response = get_response(request)
  File "/usr/local/lib/python2.7/site-packages/django/core/handlers/base.py", line 187, in _get_response
    response = self.process_exception_by_middleware(e, request)
  File "/usr/local/lib/python2.7/site-packages/django/core/handlers/base.py", line 185, in _get_response
    response = wrapped_callback(request, *callback_args, **callback_kwargs)
  File "/Users/sherry/Desktop/pythonProject/Django/django_web/api/uploadView.py", line 36, in fileList
    m = ApiCase.objects.get(id=a.api_id)
  File "/usr/local/lib/python2.7/site-packages/django/db/models/manager.py", line 85, in manager_method
    return getattr(self.get_queryset(), name)(*args, **kwargs)
  File "/usr/local/lib/python2.7/site-packages/django/db/models/query.py", line 380, in get
    self.model._meta.object_name
DoesNotExist: ApiCase matching query does not exist.
2019-04-28 13:44:06,781 - /usr/local/lib/python2.7/site-packages/django/core/handlers/exception.py[line:135] - ERROR: Internal Server Error: /bugStatistics/pbList/
Traceback (most recent call last):
  File "/usr/local/lib/python2.7/site-packages/django/core/handlers/exception.py", line 41, in inner
    response = get_response(request)
  File "/usr/local/lib/python2.7/site-packages/django/core/handlers/base.py", line 187, in _get_response
    response = self.process_exception_by_middleware(e, request)
  File "/usr/local/lib/python2.7/site-packages/django/core/handlers/base.py", line 185, in _get_response
    response = wrapped_callback(request, *callback_args, **callback_kwargs)
  File "/Users/sherry/Desktop/pythonProject/Django/bugStatistics/stViews/bugStView.py", line 38, in pbList
    total = p.count()
  File "/usr/local/lib/python2.7/site-packages/django/db/models/query.py", line 364, in count
    return self.query.get_count(using=self.db)
  File "/usr/local/lib/python2.7/site-packages/django/db/models/sql/query.py", line 499, in get_count
    number = obj.get_aggregation(using, ['__count'])['__count']
  File "/usr/local/lib/python2.7/site-packages/django/db/models/sql/query.py", line 479, in get_aggregation
    compiler = outer_query.get_compiler(using)
  File "/usr/local/lib/python2.7/site-packages/django/db/models/sql/query.py", line 255, in get_compiler
    connection = connections[using]
  File "/usr/local/lib/python2.7/site-packages/django/db/utils.py", line 208, in __getitem__
    self.ensure_defaults(alias)
  File "/usr/local/lib/python2.7/site-packages/django/db/utils.py", line 178, in ensure_defaults
    raise ConnectionDoesNotExist("The connection %s doesn't exist" % alias)
ConnectionDoesNotExist: The connection chandao doesn't exist
2019-04-28 13:44:06,822 - /usr/local/lib/python2.7/site-packages/django/core/handlers/exception.py[line:135] - ERROR: Internal Server Error: /bugStatistics/bugProjectName/
Traceback (most recent call last):
  File "/usr/local/lib/python2.7/site-packages/django/core/handlers/exception.py", line 41, in inner
    response = get_response(request)
  File "/usr/local/lib/python2.7/site-packages/django/core/handlers/base.py", line 187, in _get_response
    response = self.process_exception_by_middleware(e, request)
  File "/usr/local/lib/python2.7/site-packages/django/core/handlers/base.py", line 185, in _get_response
    response = wrapped_callback(request, *callback_args, **callback_kwargs)
  File "/usr/local/lib/python2.7/site-packages/django/contrib/auth/decorators.py", line 23, in _wrapped_view
    return view_func(request, *args, **kwargs)
  File "/Users/sherry/Desktop/pythonProject/Django/bugStatistics/stViews/bugStView.py", line 201, in bugProjectName
    for a in p:
  File "/usr/local/lib/python2.7/site-packages/django/db/models/query.py", line 250, in __iter__
    self._fetch_all()
  File "/usr/local/lib/python2.7/site-packages/django/db/models/query.py", line 1118, in _fetch_all
    self._result_cache = list(self._iterable_class(self))
  File "/usr/local/lib/python2.7/site-packages/django/db/models/query.py", line 53, in __iter__
    results = compiler.execute_sql(chunked_fetch=self.chunked_fetch)
  File "/usr/local/lib/python2.7/site-packages/django/db/models/sql/compiler.py", line 894, in execute_sql
    raise original_exception
ProgrammingError: (1146, "Table 'autoapi.zt_product' doesn't exist")
2019-04-28 13:44:07,243 - /usr/local/lib/python2.7/site-packages/django/core/handlers/exception.py[line:135] - ERROR: Internal Server Error: /bugStatistics/testerList/
Traceback (most recent call last):
  File "/usr/local/lib/python2.7/site-packages/django/core/handlers/exception.py", line 41, in inner
    response = get_response(request)
  File "/usr/local/lib/python2.7/site-packages/django/core/handlers/base.py", line 187, in _get_response
    response = self.process_exception_by_middleware(e, request)
  File "/usr/local/lib/python2.7/site-packages/django/core/handlers/base.py", line 185, in _get_response
    response = wrapped_callback(request, *callback_args, **callback_kwargs)
  File "/Users/sherry/Desktop/pythonProject/Django/bugStatistics/stViews/bugStView.py", line 94, in testerList
    total = p.count()
  File "/usr/local/lib/python2.7/site-packages/django/db/models/query.py", line 364, in count
    return self.query.get_count(using=self.db)
  File "/usr/local/lib/python2.7/site-packages/django/db/models/sql/query.py", line 499, in get_count
    number = obj.get_aggregation(using, ['__count'])['__count']
  File "/usr/local/lib/python2.7/site-packages/django/db/models/sql/query.py", line 479, in get_aggregation
    compiler = outer_query.get_compiler(using)
  File "/usr/local/lib/python2.7/site-packages/django/db/models/sql/query.py", line 255, in get_compiler
    connection = connections[using]
  File "/usr/local/lib/python2.7/site-packages/django/db/utils.py", line 208, in __getitem__
    self.ensure_defaults(alias)
  File "/usr/local/lib/python2.7/site-packages/django/db/utils.py", line 178, in ensure_defaults
    raise ConnectionDoesNotExist("The connection %s doesn't exist" % alias)
ConnectionDoesNotExist: The connection chandao doesn't exist
2019-04-28 13:44:07,674 - /usr/local/lib/python2.7/site-packages/django/core/handlers/exception.py[line:135] - ERROR: Internal Server Error: /bugStatistics/devList/
Traceback (most recent call last):
  File "/usr/local/lib/python2.7/site-packages/django/core/handlers/exception.py", line 41, in inner
    response = get_response(request)
  File "/usr/local/lib/python2.7/site-packages/django/core/handlers/base.py", line 187, in _get_response
    response = self.process_exception_by_middleware(e, request)
  File "/usr/local/lib/python2.7/site-packages/django/core/handlers/base.py", line 185, in _get_response
    response = wrapped_callback(request, *callback_args, **callback_kwargs)
  File "/Users/sherry/Desktop/pythonProject/Django/bugStatistics/stViews/bugStView.py", line 160, in devList
    total = p.count()
  File "/usr/local/lib/python2.7/site-packages/django/db/models/query.py", line 364, in count
    return self.query.get_count(using=self.db)
  File "/usr/local/lib/python2.7/site-packages/django/db/models/sql/query.py", line 499, in get_count
    number = obj.get_aggregation(using, ['__count'])['__count']
  File "/usr/local/lib/python2.7/site-packages/django/db/models/sql/query.py", line 479, in get_aggregation
    compiler = outer_query.get_compiler(using)
  File "/usr/local/lib/python2.7/site-packages/django/db/models/sql/query.py", line 255, in get_compiler
    connection = connections[using]
  File "/usr/local/lib/python2.7/site-packages/django/db/utils.py", line 208, in __getitem__
    self.ensure_defaults(alias)
  File "/usr/local/lib/python2.7/site-packages/django/db/utils.py", line 178, in ensure_defaults
    raise ConnectionDoesNotExist("The connection %s doesn't exist" % alias)
ConnectionDoesNotExist: The connection chandao doesn't exist
2019-04-28 13:44:07,714 - /usr/local/lib/python2.7/site-packages/django/core/handlers/exception.py[line:135] - ERROR: Internal Server Error: /bugStatistics/bugDevName/
Traceback (most recent call last):
  File "/usr/local/lib/python2.7/site-packages/django/core/handlers/exception.py", line 41, in inner
    response = get_response(request)
  File "/usr/local/lib/python2.7/site-packages/django/core/handlers/base.py", line 187, in _get_response
    response = self.process_exception_by_middleware(e, request)
  File "/usr/local/lib/python2.7/site-packages/django/core/handlers/base.py", line 185, in _get_response
    response = wrapped_callback(request, *callback_args, **callback_kwargs)
  File "/usr/local/lib/python2.7/site-packages/django/contrib/auth/decorators.py", line 23, in _wrapped_view
    return view_func(request, *args, **kwargs)
  File "/Users/sherry/Desktop/pythonProject/Django/bugStatistics/stViews/bugStView.py", line 212, in bugDevName
    for a in p:
  File "/usr/local/lib/python2.7/site-packages/django/db/models/query.py", line 250, in __iter__
    self._fetch_all()
  File "/usr/local/lib/python2.7/site-packages/django/db/models/query.py", line 1118, in _fetch_all
    self._result_cache = list(self._iterable_class(self))
  File "/usr/local/lib/python2.7/site-packages/django/db/models/query.py", line 53, in __iter__
    results = compiler.execute_sql(chunked_fetch=self.chunked_fetch)
  File "/usr/local/lib/python2.7/site-packages/django/db/models/sql/compiler.py", line 894, in execute_sql
    raise original_exception
ProgrammingError: (1146, "Table 'autoapi.zt_user' doesn't exist")
