2019-02-14 11:42:28,193 - /usr/local/lib/python2.7/site-packages/apscheduler/schedulers/base.py[line:162] - INFO: Scheduler started
2019-02-14 11:42:28,193 - /usr/local/lib/python2.7/site-packages/apscheduler/schedulers/base.py[line:937] - DEBUG: Looking for jobs to run
2019-02-14 11:42:28,195 - /usr/local/lib/python2.7/site-packages/apscheduler/schedulers/base.py[line:1013] - DEBUG: No jobs; waiting until a job is added
2019-02-14 11:42:38,456 - /usr/local/lib/python2.7/site-packages/urllib3/connectionpool.py[line:813] - DEBUG: Starting new HTTPS connection (1): test-zhacjavaapi.zje.com:443
2019-02-14 11:42:38,513 - /usr/local/lib/python2.7/site-packages/urllib3/connectionpool.py[line:393] - DEBUG: https://test-zhacjavaapi.zje.com:443 "POST /actmgt/user/login HTTP/1.1" 200 None
2019-02-14 11:43:15,828 - /usr/local/lib/python2.7/site-packages/django/core/handlers/exception.py[line:135] - ERROR: Internal Server Error: /autoApiSimpleRun/
Traceback (most recent call last):
  File "/usr/local/lib/python2.7/site-packages/django/core/handlers/exception.py", line 41, in inner
    response = get_response(request)
  File "/usr/local/lib/python2.7/site-packages/django/core/handlers/base.py", line 187, in _get_response
    response = self.process_exception_by_middleware(e, request)
  File "/usr/local/lib/python2.7/site-packages/django/core/handlers/base.py", line 185, in _get_response
    response = wrapped_callback(request, *callback_args, **callback_kwargs)
  File "/Users/sherry/Desktop/pythonProject/Django/django_web/api/caseApiView.py", line 438, in autoApiSimpleRun
    env = Env.objects.get(id=env_id)
  File "/usr/local/lib/python2.7/site-packages/django/db/models/manager.py", line 85, in manager_method
    return getattr(self.get_queryset(), name)(*args, **kwargs)
  File "/usr/local/lib/python2.7/site-packages/django/db/models/query.py", line 371, in get
    clone = self.filter(*args, **kwargs)
  File "/usr/local/lib/python2.7/site-packages/django/db/models/query.py", line 784, in filter
    return self._filter_or_exclude(False, *args, **kwargs)
  File "/usr/local/lib/python2.7/site-packages/django/db/models/query.py", line 802, in _filter_or_exclude
    clone.query.add_q(Q(*args, **kwargs))
  File "/usr/local/lib/python2.7/site-packages/django/db/models/sql/query.py", line 1250, in add_q
    clause, _ = self._add_q(q_object, self.used_aliases)
  File "/usr/local/lib/python2.7/site-packages/django/db/models/sql/query.py", line 1276, in _add_q
    allow_joins=allow_joins, split_subq=split_subq,
  File "/usr/local/lib/python2.7/site-packages/django/db/models/sql/query.py", line 1210, in build_filter
    condition = self.build_lookup(lookups, col, value)
  File "/usr/local/lib/python2.7/site-packages/django/db/models/sql/query.py", line 1104, in build_lookup
    return final_lookup(lhs, rhs)
  File "/usr/local/lib/python2.7/site-packages/django/db/models/lookups.py", line 24, in __init__
    self.rhs = self.get_prep_lookup()
  File "/usr/local/lib/python2.7/site-packages/django/db/models/lookups.py", line 74, in get_prep_lookup
    return self.lhs.output_field.get_prep_value(self.rhs)
  File "/usr/local/lib/python2.7/site-packages/django/db/models/fields/__init__.py", line 966, in get_prep_value
    return int(value)
UnicodeEncodeError: 'decimal' codec can't encode characters in position 0-2: invalid decimal Unicode string
2019-02-14 11:43:23,358 - /usr/local/lib/python2.7/site-packages/urllib3/connectionpool.py[line:813] - DEBUG: Starting new HTTPS connection (1): test-zhacjavaapi.zje.com:443
2019-02-14 11:43:23,427 - /usr/local/lib/python2.7/site-packages/urllib3/connectionpool.py[line:393] - DEBUG: https://test-zhacjavaapi.zje.com:443 "POST /actmgt/user/login HTTP/1.1" 200 None
2019-02-14 11:45:33,644 - /usr/local/lib/python2.7/site-packages/urllib3/connectionpool.py[line:813] - DEBUG: Starting new HTTPS connection (1): test-zhacjavaapi.zje.com:443
2019-02-14 11:45:33,703 - /usr/local/lib/python2.7/site-packages/urllib3/connectionpool.py[line:393] - DEBUG: https://test-zhacjavaapi.zje.com:443 "POST /actmgt/user/login2323 HTTP/1.1" 404 None
2019-02-14 11:45:48,866 - /usr/local/lib/python2.7/site-packages/urllib3/connectionpool.py[line:813] - DEBUG: Starting new HTTPS connection (1): test-zhacjavaapi.zje.com:443
2019-02-14 11:45:48,927 - /usr/local/lib/python2.7/site-packages/urllib3/connectionpool.py[line:393] - DEBUG: https://test-zhacjavaapi.zje.com:443 "POST /actmgt/user/login2323 HTTP/1.1" 404 None
2019-02-14 11:45:56,912 - /usr/local/lib/python2.7/site-packages/urllib3/connectionpool.py[line:813] - DEBUG: Starting new HTTPS connection (1): test-zhacjavaapi.zje.com:443
2019-02-14 11:45:56,965 - /usr/local/lib/python2.7/site-packages/urllib3/connectionpool.py[line:393] - DEBUG: https://test-zhacjavaapi.zje.com:443 "GET /actmgt/user/login2323 HTTP/1.1" 404 None
2019-02-14 11:46:12,162 - /usr/local/lib/python2.7/site-packages/urllib3/connectionpool.py[line:813] - DEBUG: Starting new HTTPS connection (1): test-zhacjavaapi.zje.com:443
2019-02-14 11:46:12,214 - /usr/local/lib/python2.7/site-packages/urllib3/connectionpool.py[line:393] - DEBUG: https://test-zhacjavaapi.zje.com:443 "GET /actmgt/user/login HTTP/1.1" 200 None
2019-02-14 12:36:44,451 - /usr/local/lib/python2.7/site-packages/django/core/handlers/exception.py[line:135] - ERROR: Internal Server Error: /autoApiSimpleRun/
Traceback (most recent call last):
  File "/usr/local/lib/python2.7/site-packages/django/core/handlers/exception.py", line 41, in inner
    response = get_response(request)
  File "/usr/local/lib/python2.7/site-packages/django/core/handlers/base.py", line 187, in _get_response
    response = self.process_exception_by_middleware(e, request)
  File "/usr/local/lib/python2.7/site-packages/django/core/handlers/base.py", line 185, in _get_response
    response = wrapped_callback(request, *callback_args, **callback_kwargs)
  File "/Users/sherry/Desktop/pythonProject/Django/django_web/api/caseApiView.py", line 438, in autoApiSimpleRun
    env = Env.objects.get(id=env_id)
  File "/usr/local/lib/python2.7/site-packages/django/db/models/manager.py", line 85, in manager_method
    return getattr(self.get_queryset(), name)(*args, **kwargs)
  File "/usr/local/lib/python2.7/site-packages/django/db/models/query.py", line 371, in get
    clone = self.filter(*args, **kwargs)
  File "/usr/local/lib/python2.7/site-packages/django/db/models/query.py", line 784, in filter
    return self._filter_or_exclude(False, *args, **kwargs)
  File "/usr/local/lib/python2.7/site-packages/django/db/models/query.py", line 802, in _filter_or_exclude
    clone.query.add_q(Q(*args, **kwargs))
  File "/usr/local/lib/python2.7/site-packages/django/db/models/sql/query.py", line 1250, in add_q
    clause, _ = self._add_q(q_object, self.used_aliases)
  File "/usr/local/lib/python2.7/site-packages/django/db/models/sql/query.py", line 1276, in _add_q
    allow_joins=allow_joins, split_subq=split_subq,
  File "/usr/local/lib/python2.7/site-packages/django/db/models/sql/query.py", line 1210, in build_filter
    condition = self.build_lookup(lookups, col, value)
  File "/usr/local/lib/python2.7/site-packages/django/db/models/sql/query.py", line 1104, in build_lookup
    return final_lookup(lhs, rhs)
  File "/usr/local/lib/python2.7/site-packages/django/db/models/lookups.py", line 24, in __init__
    self.rhs = self.get_prep_lookup()
  File "/usr/local/lib/python2.7/site-packages/django/db/models/lookups.py", line 74, in get_prep_lookup
    return self.lhs.output_field.get_prep_value(self.rhs)
  File "/usr/local/lib/python2.7/site-packages/django/db/models/fields/__init__.py", line 966, in get_prep_value
    return int(value)
UnicodeEncodeError: 'decimal' codec can't encode characters in position 0-2: invalid decimal Unicode string
2019-02-14 12:37:07,622 - /usr/local/lib/python2.7/site-packages/urllib3/connectionpool.py[line:813] - DEBUG: Starting new HTTPS connection (1): test-zhacjavaapi.zje.com:443
2019-02-14 12:37:07,677 - /usr/local/lib/python2.7/site-packages/urllib3/connectionpool.py[line:393] - DEBUG: https://test-zhacjavaapi.zje.com:443 "GET /actmgt/user/login HTTP/1.1" 200 None
2019-02-14 12:37:14,130 - /usr/local/lib/python2.7/site-packages/urllib3/connectionpool.py[line:813] - DEBUG: Starting new HTTPS connection (1): test-zhacjavaapi.zje.com:443
2019-02-14 12:37:14,185 - /usr/local/lib/python2.7/site-packages/urllib3/connectionpool.py[line:393] - DEBUG: https://test-zhacjavaapi.zje.com:443 "POST /actmgt/user/login HTTP/1.1" 200 None
2019-02-14 13:11:59,634 - /usr/local/lib/python2.7/site-packages/urllib3/connectionpool.py[line:813] - DEBUG: Starting new HTTPS connection (1): test-zhacjavaapi.zje.com:443
2019-02-14 13:11:59,702 - /usr/local/lib/python2.7/site-packages/urllib3/connectionpool.py[line:393] - DEBUG: https://test-zhacjavaapi.zje.com:443 "POST /actmgt/user/login HTTP/1.1" 200 None
2019-02-14 13:35:25,707 - /usr/local/lib/python2.7/site-packages/urllib3/connectionpool.py[line:813] - DEBUG: Starting new HTTPS connection (1): test-zhacjavaapi.zje.com:443
2019-02-14 13:35:25,773 - /usr/local/lib/python2.7/site-packages/urllib3/connectionpool.py[line:393] - DEBUG: https://test-zhacjavaapi.zje.com:443 "POST /actmgt/user/login HTTP/1.1" 200 None
2019-02-14 13:58:50,194 - /usr/local/lib/python2.7/site-packages/urllib3/connectionpool.py[line:813] - DEBUG: Starting new HTTPS connection (1): test-zhacjavaapi.zje.com:443
2019-02-14 13:58:50,274 - /usr/local/lib/python2.7/site-packages/urllib3/connectionpool.py[line:393] - DEBUG: https://test-zhacjavaapi.zje.com:443 "POST /actmgt/user/login HTTP/1.1" 200 None
2019-02-14 14:30:46,939 - /usr/local/lib/python2.7/site-packages/django/core/handlers/exception.py[line:135] - ERROR: Internal Server Error: /autoApiSimpleRun/
Traceback (most recent call last):
  File "/usr/local/lib/python2.7/site-packages/django/core/handlers/exception.py", line 41, in inner
    response = get_response(request)
  File "/usr/local/lib/python2.7/site-packages/django/core/handlers/base.py", line 187, in _get_response
    response = self.process_exception_by_middleware(e, request)
  File "/usr/local/lib/python2.7/site-packages/django/core/handlers/base.py", line 185, in _get_response
    response = wrapped_callback(request, *callback_args, **callback_kwargs)
  File "/Users/sherry/Desktop/pythonProject/Django/django_web/api/caseApiView.py", line 438, in autoApiSimpleRun
    env = Env.objects.get(id=env_id)
  File "/usr/local/lib/python2.7/site-packages/django/db/models/manager.py", line 85, in manager_method
    return getattr(self.get_queryset(), name)(*args, **kwargs)
  File "/usr/local/lib/python2.7/site-packages/django/db/models/query.py", line 371, in get
    clone = self.filter(*args, **kwargs)
  File "/usr/local/lib/python2.7/site-packages/django/db/models/query.py", line 784, in filter
    return self._filter_or_exclude(False, *args, **kwargs)
  File "/usr/local/lib/python2.7/site-packages/django/db/models/query.py", line 802, in _filter_or_exclude
    clone.query.add_q(Q(*args, **kwargs))
  File "/usr/local/lib/python2.7/site-packages/django/db/models/sql/query.py", line 1250, in add_q
    clause, _ = self._add_q(q_object, self.used_aliases)
  File "/usr/local/lib/python2.7/site-packages/django/db/models/sql/query.py", line 1276, in _add_q
    allow_joins=allow_joins, split_subq=split_subq,
  File "/usr/local/lib/python2.7/site-packages/django/db/models/sql/query.py", line 1210, in build_filter
    condition = self.build_lookup(lookups, col, value)
  File "/usr/local/lib/python2.7/site-packages/django/db/models/sql/query.py", line 1104, in build_lookup
    return final_lookup(lhs, rhs)
  File "/usr/local/lib/python2.7/site-packages/django/db/models/lookups.py", line 24, in __init__
    self.rhs = self.get_prep_lookup()
  File "/usr/local/lib/python2.7/site-packages/django/db/models/lookups.py", line 74, in get_prep_lookup
    return self.lhs.output_field.get_prep_value(self.rhs)
  File "/usr/local/lib/python2.7/site-packages/django/db/models/fields/__init__.py", line 966, in get_prep_value
    return int(value)
UnicodeEncodeError: 'decimal' codec can't encode characters in position 0-2: invalid decimal Unicode string
2019-02-14 16:13:49,423 - /usr/local/lib/python2.7/site-packages/urllib3/connectionpool.py[line:813] - DEBUG: Starting new HTTPS connection (1): test-zhacjavaapi.zje.com:443
2019-02-14 16:13:49,488 - /usr/local/lib/python2.7/site-packages/urllib3/connectionpool.py[line:393] - DEBUG: https://test-zhacjavaapi.zje.com:443 "POST /actmgt/user/login HTTP/1.1" 200 None
2019-02-14 17:01:29,685 - /usr/local/lib/python2.7/site-packages/urllib3/connectionpool.py[line:813] - DEBUG: Starting new HTTPS connection (1): test-zhacjavaapi.zje.com:443
2019-02-14 17:01:29,748 - /usr/local/lib/python2.7/site-packages/urllib3/connectionpool.py[line:393] - DEBUG: https://test-zhacjavaapi.zje.com:443 "POST /actmgt/user/login HTTP/1.1" 200 None
2019-02-14 17:05:55,159 - /usr/local/lib/python2.7/site-packages/urllib3/connectionpool.py[line:813] - DEBUG: Starting new HTTPS connection (1): test-zhacjavaapi.zje.com:443
2019-02-14 17:05:55,233 - /usr/local/lib/python2.7/site-packages/urllib3/connectionpool.py[line:393] - DEBUG: https://test-zhacjavaapi.zje.com:443 "POST /actmgt/user/login HTTP/1.1" 200 None
2019-02-14 19:56:59,529 - /usr/local/lib/python2.7/site-packages/urllib3/connectionpool.py[line:813] - DEBUG: Starting new HTTPS connection (1): zhacjavaapi.zje.com:443
2019-02-14 19:57:00,338 - /usr/local/lib/python2.7/site-packages/urllib3/connectionpool.py[line:813] - DEBUG: Starting new HTTPS connection (1): zhacjavaapi.zje.com:443
2019-02-14 19:57:00,596 - /usr/local/lib/python2.7/site-packages/urllib3/connectionpool.py[line:393] - DEBUG: https://zhacjavaapi.zje.com:443 "POST /actmgt/user/login2323 HTTP/1.1" 404 None
2019-02-14 19:57:00,629 - /usr/local/lib/python2.7/site-packages/urllib3/connectionpool.py[line:813] - DEBUG: Starting new HTTPS connection (1): zhacjavaapi.zje.com:443
2019-02-14 19:57:01,165 - /usr/local/lib/python2.7/site-packages/urllib3/connectionpool.py[line:393] - DEBUG: https://zhacjavaapi.zje.com:443 "POST /actmgt/user/login2323 HTTP/1.1" 404 None
2019-02-14 19:57:01,200 - /usr/local/lib/python2.7/site-packages/urllib3/connectionpool.py[line:813] - DEBUG: Starting new HTTPS connection (1): zhacjavaapi.zje.com:443
2019-02-14 19:57:01,404 - /usr/local/lib/python2.7/site-packages/urllib3/connectionpool.py[line:393] - DEBUG: https://zhacjavaapi.zje.com:443 "POST /actmgt/user/login HTTP/1.1" 404 None
2019-02-14 19:57:01,437 - /usr/local/lib/python2.7/site-packages/urllib3/connectionpool.py[line:813] - DEBUG: Starting new HTTPS connection (1): zhacjavaapi.zje.com:443
2019-02-14 19:57:02,004 - /usr/local/lib/python2.7/site-packages/urllib3/connectionpool.py[line:393] - DEBUG: https://zhacjavaapi.zje.com:443 "POST /actmgt/user/login HTTP/1.1" 404 None
2019-02-14 19:57:02,036 - /usr/local/lib/python2.7/site-packages/urllib3/connectionpool.py[line:813] - DEBUG: Starting new HTTPS connection (1): zhacjavaapi.zje.com:443
2019-02-14 19:57:02,298 - /usr/local/lib/python2.7/site-packages/urllib3/connectionpool.py[line:393] - DEBUG: https://zhacjavaapi.zje.com:443 "POST /actmgt/user/login HTTP/1.1" 404 None
2019-02-14 19:57:02,332 - /usr/local/lib/python2.7/site-packages/urllib3/connectionpool.py[line:813] - DEBUG: Starting new HTTPS connection (1): zhacjavaapi.zje.com:443
2019-02-14 19:57:03,869 - /usr/local/lib/python2.7/site-packages/urllib3/connectionpool.py[line:393] - DEBUG: https://zhacjavaapi.zje.com:443 "POST /actmgt/user/login HTTP/1.1" 404 None
2019-02-14 19:57:03,917 - /usr/local/lib/python2.7/site-packages/urllib3/connectionpool.py[line:393] - DEBUG: https://zhacjavaapi.zje.com:443 "POST /actmgt/user/login HTTP/1.1" 404 None
2019-02-14 19:57:03,950 - /usr/local/lib/python2.7/site-packages/urllib3/connectionpool.py[line:813] - DEBUG: Starting new HTTPS connection (1): zhacjavaapi.zje.com:443
2019-02-14 19:57:04,443 - /usr/local/lib/python2.7/site-packages/urllib3/connectionpool.py[line:393] - DEBUG: https://zhacjavaapi.zje.com:443 "POST /actmgt/user/login HTTP/1.1" 404 None
2019-02-14 19:57:13,039 - /usr/local/lib/python2.7/site-packages/urllib3/connectionpool.py[line:813] - DEBUG: Starting new HTTPS connection (1): test-zhacjavaapi.zje.com:443
2019-02-14 19:57:13,085 - /usr/local/lib/python2.7/site-packages/urllib3/connectionpool.py[line:393] - DEBUG: https://test-zhacjavaapi.zje.com:443 "POST /actmgt/user/login2323 HTTP/1.1" 404 None
2019-02-14 19:57:13,096 - /usr/local/lib/python2.7/site-packages/urllib3/connectionpool.py[line:813] - DEBUG: Starting new HTTPS connection (1): test-zhacjavaapi.zje.com:443
2019-02-14 19:57:13,158 - /usr/local/lib/python2.7/site-packages/urllib3/connectionpool.py[line:393] - DEBUG: https://test-zhacjavaapi.zje.com:443 "POST /actmgt/user/login HTTP/1.1" 200 None
2019-02-14 19:57:13,169 - /usr/local/lib/python2.7/site-packages/urllib3/connectionpool.py[line:813] - DEBUG: Starting new HTTPS connection (1): test-zhacjavaapi.zje.com:443
2019-02-14 19:57:13,218 - /usr/local/lib/python2.7/site-packages/urllib3/connectionpool.py[line:393] - DEBUG: https://test-zhacjavaapi.zje.com:443 "POST /actmgt/user/login HTTP/1.1" 200 None
2019-02-14 19:57:13,230 - /usr/local/lib/python2.7/site-packages/urllib3/connectionpool.py[line:813] - DEBUG: Starting new HTTPS connection (1): test-zhacjavaapi.zje.com:443
2019-02-14 19:57:13,297 - /usr/local/lib/python2.7/site-packages/urllib3/connectionpool.py[line:393] - DEBUG: https://test-zhacjavaapi.zje.com:443 "POST /actmgt/user/login HTTP/1.1" 200 None
