2019-02-12 18:28:37,658 - /usr/local/lib/python2.7/site-packages/apscheduler/schedulers/base.py[line:162] - INFO: Scheduler started
2019-02-12 18:28:37,659 - /usr/local/lib/python2.7/site-packages/apscheduler/schedulers/base.py[line:937] - DEBUG: Looking for jobs to run
2019-02-12 18:28:37,660 - /usr/local/lib/python2.7/site-packages/apscheduler/schedulers/base.py[line:1013] - DEBUG: No jobs; waiting until a job is added
2019-02-12 18:36:30,297 - /usr/local/lib/python2.7/site-packages/django/core/handlers/exception.py[line:135] - ERROR: Internal Server Error: /bugStatistics/pbList/
Traceback (most recent call last):
  File "/usr/local/lib/python2.7/site-packages/django/core/handlers/exception.py", line 41, in inner
    response = get_response(request)
  File "/usr/local/lib/python2.7/site-packages/django/core/handlers/base.py", line 187, in _get_response
    response = self.process_exception_by_middleware(e, request)
  File "/usr/local/lib/python2.7/site-packages/django/core/handlers/base.py", line 185, in _get_response
    response = wrapped_callback(request, *callback_args, **callback_kwargs)
  File "/Users/sherry/Desktop/pythonProject/Django/bugStatistics/stViews/bugStView.py", line 36, in pbList
    total = p.count()
  File "/usr/local/lib/python2.7/site-packages/django/db/models/query.py", line 364, in count
    return self.query.get_count(using=self.db)
  File "/usr/local/lib/python2.7/site-packages/django/db/models/sql/query.py", line 499, in get_count
    number = obj.get_aggregation(using, ['__count'])['__count']
  File "/usr/local/lib/python2.7/site-packages/django/db/models/sql/query.py", line 479, in get_aggregation
    compiler = outer_query.get_compiler(using)
  File "/usr/local/lib/python2.7/site-packages/django/db/models/sql/query.py", line 255, in get_compiler
    connection = connections[using]
  File "/usr/local/lib/python2.7/site-packages/django/db/utils.py", line 208, in __getitem__
    self.ensure_defaults(alias)
  File "/usr/local/lib/python2.7/site-packages/django/db/utils.py", line 178, in ensure_defaults
    raise ConnectionDoesNotExist("The connection %s doesn't exist" % alias)
ConnectionDoesNotExist: The connection chandao doesn't exist
2019-02-12 18:36:30,335 - /usr/local/lib/python2.7/site-packages/django/core/handlers/exception.py[line:135] - ERROR: Internal Server Error: /bugStatistics/bugProjectName/
Traceback (most recent call last):
  File "/usr/local/lib/python2.7/site-packages/django/core/handlers/exception.py", line 41, in inner
    response = get_response(request)
  File "/usr/local/lib/python2.7/site-packages/django/core/handlers/base.py", line 187, in _get_response
    response = self.process_exception_by_middleware(e, request)
  File "/usr/local/lib/python2.7/site-packages/django/core/handlers/base.py", line 185, in _get_response
    response = wrapped_callback(request, *callback_args, **callback_kwargs)
  File "/usr/local/lib/python2.7/site-packages/django/contrib/auth/decorators.py", line 23, in _wrapped_view
    return view_func(request, *args, **kwargs)
  File "/Users/sherry/Desktop/pythonProject/Django/bugStatistics/stViews/bugStView.py", line 199, in bugProjectName
    for a in p:
  File "/usr/local/lib/python2.7/site-packages/django/db/models/query.py", line 250, in __iter__
    self._fetch_all()
  File "/usr/local/lib/python2.7/site-packages/django/db/models/query.py", line 1118, in _fetch_all
    self._result_cache = list(self._iterable_class(self))
  File "/usr/local/lib/python2.7/site-packages/django/db/models/query.py", line 53, in __iter__
    results = compiler.execute_sql(chunked_fetch=self.chunked_fetch)
  File "/usr/local/lib/python2.7/site-packages/django/db/models/sql/compiler.py", line 894, in execute_sql
    raise original_exception
ProgrammingError: (1146, "Table 'autoapi.zt_product' doesn't exist")
2019-02-12 18:36:32,053 - /usr/local/lib/python2.7/site-packages/django/core/handlers/exception.py[line:135] - ERROR: Internal Server Error: /bugStatistics/pbList/
Traceback (most recent call last):
  File "/usr/local/lib/python2.7/site-packages/django/core/handlers/exception.py", line 41, in inner
    response = get_response(request)
  File "/usr/local/lib/python2.7/site-packages/django/core/handlers/base.py", line 187, in _get_response
    response = self.process_exception_by_middleware(e, request)
  File "/usr/local/lib/python2.7/site-packages/django/core/handlers/base.py", line 185, in _get_response
    response = wrapped_callback(request, *callback_args, **callback_kwargs)
  File "/Users/sherry/Desktop/pythonProject/Django/bugStatistics/stViews/bugStView.py", line 36, in pbList
    total = p.count()
  File "/usr/local/lib/python2.7/site-packages/django/db/models/query.py", line 364, in count
    return self.query.get_count(using=self.db)
  File "/usr/local/lib/python2.7/site-packages/django/db/models/sql/query.py", line 499, in get_count
    number = obj.get_aggregation(using, ['__count'])['__count']
  File "/usr/local/lib/python2.7/site-packages/django/db/models/sql/query.py", line 479, in get_aggregation
    compiler = outer_query.get_compiler(using)
  File "/usr/local/lib/python2.7/site-packages/django/db/models/sql/query.py", line 255, in get_compiler
    connection = connections[using]
  File "/usr/local/lib/python2.7/site-packages/django/db/utils.py", line 208, in __getitem__
    self.ensure_defaults(alias)
  File "/usr/local/lib/python2.7/site-packages/django/db/utils.py", line 178, in ensure_defaults
    raise ConnectionDoesNotExist("The connection %s doesn't exist" % alias)
ConnectionDoesNotExist: The connection chandao doesn't exist
2019-02-12 18:36:32,092 - /usr/local/lib/python2.7/site-packages/django/core/handlers/exception.py[line:135] - ERROR: Internal Server Error: /bugStatistics/bugProjectName/
Traceback (most recent call last):
  File "/usr/local/lib/python2.7/site-packages/django/core/handlers/exception.py", line 41, in inner
    response = get_response(request)
  File "/usr/local/lib/python2.7/site-packages/django/core/handlers/base.py", line 187, in _get_response
    response = self.process_exception_by_middleware(e, request)
  File "/usr/local/lib/python2.7/site-packages/django/core/handlers/base.py", line 185, in _get_response
    response = wrapped_callback(request, *callback_args, **callback_kwargs)
  File "/usr/local/lib/python2.7/site-packages/django/contrib/auth/decorators.py", line 23, in _wrapped_view
    return view_func(request, *args, **kwargs)
  File "/Users/sherry/Desktop/pythonProject/Django/bugStatistics/stViews/bugStView.py", line 199, in bugProjectName
    for a in p:
  File "/usr/local/lib/python2.7/site-packages/django/db/models/query.py", line 250, in __iter__
    self._fetch_all()
  File "/usr/local/lib/python2.7/site-packages/django/db/models/query.py", line 1118, in _fetch_all
    self._result_cache = list(self._iterable_class(self))
  File "/usr/local/lib/python2.7/site-packages/django/db/models/query.py", line 53, in __iter__
    results = compiler.execute_sql(chunked_fetch=self.chunked_fetch)
  File "/usr/local/lib/python2.7/site-packages/django/db/models/sql/compiler.py", line 894, in execute_sql
    raise original_exception
ProgrammingError: (1146, "Table 'autoapi.zt_product' doesn't exist")
